Workbook

Sheet Инструкция
A1: Универсальный шаблон канонической модели производственной системы
A2: Рабочий инструмент для системного описания любой производственной системы: от продукта и контрактов до процессов, действий, состояний, данных и исполнения.
A4: 1. Как заполнять
A5: 1 | B5: Система | C5: Создайте производственную систему и её продукт. Укажите получателя и критерии приёмки продукта.
A6: 2 | B6: Источники | C6: Зарегистрируйте решения владельца, регламенты, живые системы, встречи и гипотезы.
A7: 3 | B7: Версии | C7: Создайте версию текущей или целевой модели. Принятая версия не редактируется задним числом.
A8: 4 | B8: Позиции | C8: Опишите ответственность, результат и полномочия. Затем отдельно назначьте людей или AI-агентов.
A9: 5 | B9: Объекты и состояния | C9: Опишите объект работы, допустимые состояния и критерии каждого состояния.
A10: 6 | B10: Процессы | C10: Зафиксируйте цель, триггер, вход, выход, владельца и связь с продуктом.
A11: 7 | B11: Действия и связи | C11: Разложите процесс до исполнимых действий; задайте порядок, решения, исключения и возвраты.
A12: 8 | B12: Действия, связи и диаграммы | C12: Разложите процесс до исполнимых действий; задайте порядок, решения, исключения и возвраты. Затем создайте diagram_id и проверьте вычисляемую проекцию draw.io.
A13: 9 | B13: Элементы и контракты | C13: Подключите регламенты, правила, данные, ИС, интерфейсы, метрики, SLA и межсистемные контракты.
A14: 10 | B14: Проверки | C14: Исправьте ошибки целостности и осознанно оставьте только документированные неизвестные.
A16: 2. Базовые правила модели
A17: Производственная система | B17: Корневой уровень. Она производит продукт для конкретного получателя.
A18: Продукт | B18: Не просто результат, а объект передачи с критериями приёмки принимающей стороной.
A19: Процесс | B19: Воспроизводимое преобразование: триггер → вход → действия → выход.
A20: Подпроцесс | B20: Тот же процесс, связанный с родительским через parent_process_id.
A21: Действие | B21: Минимальная управляемая единица работы с собственными входом, выходом и ответственной позицией.
A22: Позиция ≠ человек | B22: Ответственность живёт в позиции; конкретный исполнитель хранится в «Назначениях».
A23: Регламент ≠ процесс | B23: Регламент, правило, интерфейс и система — элементы модели, связанные с действием или процессом.
A24: Текущая модель ≠ целевая модель | B24: Текущая и целевая модели разделены слоем и версией. Нельзя смешивать факт и замысел в одной строке.
A25: Статус знания ≠ статус исполнения | B25: принято / кандидат / гипотеза / конфликт / устарело / неизвестно показывают качество знания; статус исполнения — реальную операционную практику.
A26: Живые экземпляры | B26: Карточки сделок, задач и отклонений не хранятся здесь. Этот файл — модель, не журнал операций.
A28: 3. Стабильные ID
A29: ps- | B29: производственная система
A30: prod- | B30: продукт
A31: src- | B31: источник
A32: ver- | B32: версия
A33: pos- | B33: позиция
A34: asg- | B34: назначение
A35: prc- | B35: процесс
A36: act- | B36: действие
A37: edge- | B37: связь действий
A38: obj- | B38: объект
A39: st- | B39: состояние
A40: tr- | B40: переход
... A44: dgm- | B44: диаграмма процесса
A45: 4. Критерии готовности одной модели
A46: ✓ | B46: Есть продукт, получатель и проверяемые критерии приёмки.
...

Sheet Система
A1: Система — центр настройки шаблона
A2: Здесь задаются производственные системы, продукты и все допустимые значения. Остальные листы получают отсюда выпадающие списки и проверки внешних ключей.
A3: Производственные системы
A4: ID системы system_id * | B4: Название system_name * | C4: Орг. тег org_tag | D4: Назначение purpose * | E4: Позиция-владелец owner_position_id | F4: Текущая версия current_version_id | G4: Статус знания knowledge_status * | H4: Источник source_id * | I4: Актуализировано last_reviewed * | J4: Следующий аудит next_audit | K4: Активна active *
A5: ps-001 | B5: Привлечение | C5: Модуль Привлечение | D5: Производить потенциального участника, принятого принимающей стороной и переданного в клуб с согласованным пакетом | G5: принято | H5: src-001 | I5: 46234 | K5: да
A16: Продукты систем
A17: ID продукта product_id * | B17: Система system_id * | C17: Название продукта product_name * | D17: Система-получатель recipient_system_id | E17: Позиция-получатель recipient_position_id | F17: Получатель словами recipient_description * | G17: Критерии приёмки acceptance_criteria * | H17: Состояние выхода output_state_id | I17: Контракт contract_id | J17: Статус знания knowledge_status * | K17: Источник source_id * | L17: Актуализировано last_reviewed * | M17: Примечания notes
A18: prod-001 | B18: ps-001 | C18: Потенциальный участник, принятый принимающей стороной и переданный в клуб | F18: Принимающая сторона / клуб | G18: Принимающая сторона приняла участника; согласованный пакет передан | J18: принято | K18: src-001 | L18: 46234 | M18: Подтверждённая рамка первой настройки шаблона.
A30: Управляемые словари
A32: Статус знания knowledge_status | B32: Слой модели model_layer | C32: Статус исполнения execution_status | D32: Статус жизненного цикла lifecycle_status | E32: Тип действия action_type | F32: Тип связи действий action_link_type | G32: Режим исполнения performer_mode | H32: Тип элемента element_type | I32: Тип источника source_type | J32: Тип отношения relation_type | K32: Да / нет yes_no | L32: Статус назначения assignment_status | M32: Приоритет priority | N32: Тип объекта object_type | O32: Тип триггера перехода transition_trigger_type | P32: Тип версии version_type | Q32: Статус версии version_status | R32: Авторитетность источника source_authority | S32: Тип исполнителя assignment_performer_type | V32: all_entity_ids | W32: system_ids | X32: product_ids | Y32: process_ids | Z32: action_ids | AA32: object_ids | AB32: state_ids | AC32: position_ids | AD32: element_ids | AE32: version_ids | AF32: source_ids | AG32: contract_ids | AH32: assignment_ids | AI32: action_edge_ids | AJ32: transition_ids | AK32: model_link_ids | AL32: diagram_ids
A33: принято | B33: текущая | C33: исполняется | D33: черновик | E33: работа | F33: последовательность | G33: человек | H33: регламент | I33: решение владельца | J33: производит | K33: да | L33: назначен | M33: P0 | N33: объект работы | O33: действие | P33: модель процессов | Q33: черновик | R33: 1 — решение владельца | S33: человек | V33: =IFERROR(__xludf.DUMMYFUNCTION("LET(ids,TOCOL(VSTACK(W33:W232,X33:X232,Y33:Y232,Z33:Z332,AA33:AA232,AB33:AB332,AC33:AC232,AD33:AD332,AE33:AE132,AF33:AF232,AG33:AG132,AH33:AH232,AI33:AI332,AJ33:AJ332,AK33:AK332,AL33:AL132),1),SORT(UNIQUE(FILTER(ids,ids<>""""))))"),"prod-001") -> prod-001 | W33: =IFERROR(__xludf.DUMMYFUNCTION("IFNA(FILTER($A$5:$A$14,$A$5:$A$14<>""""),"""")"),"ps-001") -> ps-001 | X33: =IFERROR(__xludf.DUMMYFUNCTION("IFNA(FILTER($A$18:$A$27,$A$18:$A$27<>""""),"""")"),"prod-001") -> prod-001 | Y33: =IFERROR(__xludf.DUMMYFUNCTION("IFNA(FILTER('Процессы'!$A$5:$A$204,'Процессы'!$A$5:$A$204<>""""),"""")"),"") | Z33: =IFERROR(__xludf.DUMMYFUNCTION("IFNA(FILTER('Действия'!$A$5:$A$304,'Действия'!$A$5:$A$304<>""""),"""")"),"") | AA33: =IFERROR(__xludf.DUMMYFUNCTION("IFNA(FILTER('Объекты'!$A$5:$A$204,'Объекты'!$A$5:$A$204<>""""),"""")"),"") | AB33: =IFERROR(__xludf.DUMMYFUNCTION("IFNA(FILTER('Состояния'!$A$5:$A$304,'Состояния'!$A$5:$A$304<>""""),"""")"),"") | AC33: =IFERROR(__xludf.DUMMYFUNCTION("IFNA(FILTER('Позиции'!$A$5:$A$204,'Позиции'!$A$5:$A$204<>""""),"""")"),"") | AD33: =IFERROR(__xludf.DUMMYFUNCTION("IFNA(FILTER('Элементы модели'!$A$5:$A$304,'Элементы модели'!$A$5:$A$304<>""""),"""")"),"") | AE33: =IFERROR(__xludf.DUMMYFUNCTION("IFNA(FILTER('Версии'!$A$5:$A$104,'Версии'!$A$5:$A$104<>""""),"""")"),"") | AF33: =IFERROR(__xludf.DUMMYFUNCTION("IFNA(FILTER('Источники'!$A$5:$A$204,'Источники'!$A$5:$A$204<>""""),"""")"),"src-001") -> src-001 | AG33: =IFERROR(__xludf.DUMMYFUNCTION("IFNA(FILTER('Контракты'!$A$5:$A$104,'Контракты'!$A$5:$A$104<>""""),"""")"),"") | AH33: =IFERROR(__xludf.DUMMYFUNCTION("IFNA(FILTER('Назначения'!$A$5:$A$204,'Назначения'!$A$5:$A$204<>""""),"""")"),"") | AI33: =IFERROR(__xludf.DUMMYFUNCTION("IFNA(FILTER('Связи действий'!$A$5:$A$304,'Связи действий'!$A$5:$A$304<>""""),"""")"),"") | AJ33: =IFERROR(__xludf.DUMMYFUNCTION("IFNA(FILTER('Переходы'!$A$5:$A$304,'Переходы'!$A$5:$A$304<>""""),"""")"),"") | AK33: =IFERROR(__xludf.DUMMYFUNCTION("IFNA(FILTER('Связи модели'!$A$5:$A$304,'Связи модели'!$A$5:$A$304<>""""),"""")"),"") | AL33: =IFERROR(__xludf.DUMMYFUNCTION("IFNA(FILTER('Диаграммы'!$A$5:$A$104,'Диаграммы'!$A$5:$A$104<>""""),"""")"),"")
A34: кандидат | B34: целевая | C34: не исполняется | D34: принято | E34: решение | F34: условие | G34: ИИ-агент | H34: правило | I34: живая система | J34: потребляет | K34: нет | L34: кандидат | M34: P1 | N34: данные | O34: событие | P34: комплект технологии | Q34: принято | R34: 2 — живая система | S34: ИИ-агент | V34: =IFERROR(__xludf.DUMMYFUNCTION("""COMPUTED_VALUE"""),"ps-001") -> ps-001 | AF34: =IFERROR(__xludf.DUMMYFUNCTION("""COMPUTED_VALUE"""),"src-002") -> src-002
A35: гипотеза | C35: уточняется | D35: действует | E35: передача | F35: ветвление | G35: автоматизация | H35: данные | I35: регламент | J35: поставляет | L35: не закреплён | M35: P2 | N35: вход | O35: условие | Q35: действует | R35: 3 — регламент / документ | V35: =IFERROR(__xludf.DUMMYFUNCTION("""COMPUTED_VALUE"""),"src-001") -> src-001
A36: конфликт | C36: не применимо | D36: заменено | E36: контроль | F36: исключение | G36: смешанный | H36: информационная система | I36: методология | J36: является частью | L36: завершён | M36: P3 | N36: выход | O36: решение | Q36: заменено | R36: 4 — дашборд / модель | V36: =IFERROR(__xludf.DUMMYFUNCTION("""COMPUTED_VALUE"""),"src-002") -> src-002
A37: устарело | D37: выведено | E37: автоматизация | F37: возврат | H37: интерфейс исполнения | I37: встреча | J37: владеет | N37: документ | Q37: выведено | R37: 5 — интервью / встреча
A38: неизвестно | E38: подпроцесс | H38: метрика | I38: кейс | J38: измеряется | N38: ресурс | R38: 6 — предположение
H39: норматив | I39: анализ | J39: источник истины
H40: уровень сервиса (SLA) | I40: гипотеза | J40: находится в состоянии
H41: автоматизация | J41: регулируется
H42: материал
A45: Служебные центральные списки ID находятся в скрытых столбцах V:AL. Они рассчитываются из реестров и являются единственным источником для проверок внешних ключей.
A48: Словари схем draw.io
A49: Русские значения используются в выпадающих списках; технические ключи в заголовках и правилах отображения сохраняют однозначную машинную интерпретацию.
A50: Тип диаграммы diagram_type | B50: Нотация diagram_notation | C50: Направление diagram_direction | D50: Дорожки diagram_lane_mode | E50: Статус синхронизации diagram_sync_status
A51: схема процесса | B51: блок-схема | C51: слева направо | D51: по позициям | E51: актуальна
A52: карта взаимодействий | B52: BPMN — упрощённая | C52: сверху вниз | D52: без дорожек | E52: требует обновления
A53: карта состояний | B53: кросс-функциональная | E53: не сгенерирована
A58: Правила отображения действий и связей в draw.io
A59: Эта таблица — контракт компилятора схем: значение модели однозначно превращается в фигуру или линию; ручная геометрия не является источником истины.
A60: Значение модели | B60: Ключ формы draw.io | C60: Фигура | D60: Правило | F60: Значение связи | G60: Ключ линии draw.io | H60: Вид линии | I60: Правило
A61: работа | B61: task | C61: скруглённый прямоугольник | D61: Исполнимая операция | F61: последовательность | G61: sequence | H61: сплошная | I61: Обычный переход
A62: решение | B62: gateway | C62: ромб | D62: У каждой исходящей ветки есть подпись; не более одной ветки по умолчанию | F62: условие | G62: condition | H62: сплошная с подписью | I62: condition_text обязателен
A63: передача | B63: transfer | C63: скруглённый прямоугольник с акцентом | D63: Смена ответственной позиции или дорожки | F63: ветвление | G63: decision | H63: сплошная с подписью | I63: branch_label обязателен
A64: контроль | B64: control | C64: скруглённый прямоугольник с контуром | D64: Проверка критерия и свидетельства | F64: исключение | G64: exception | H64: красная пунктирная | I64: Обработка отклонения
A65: автоматизация | B65: automation | C65: скруглённый прямоугольник с маркером | D65: Исполняется системой или ИИ-агентом | F65: возврат | G65: return | H65: пунктирная обратная | I65: Возврат к предыдущему действию
A66: подпроцесс | B66: subprocess | C66: прямоугольник с двойной рамкой | D66: linked_process_id обязателен
A67: начало процесса | B67: start-event | C67: круг | D67: Генерируется из стартовой связи: evt-start::<process_id>
A68: завершение процесса | B68: end-event | C68: круг с двойной рамкой | D68: Генерируется из финальной связи: evt-end::<process_id>
A70: Стабильность draw.io: ID узла = action_id; ID стрелки = edge_id; ID дорожки = lane::<position_id>; старт/финиш = evt-start::<process_id> и evt-end::<process_id>.

Sheet Схема шаблона
A1: Схема связей шаблона
A2: Эта карта отвечает на вопрос «какой столбец с чем связан». Порядок действий задаётся «Связями действий», а производная схема — листами «Диаграммы» и «Проекция draw.io».
A3: Все внешние ключи выбираются из центральных списков ID листа «Система». Свободный ввод запрещён проверкой данных.
A4: ID связи | B4: Поле-источник | C4: Кардинальность | D4: Поле-назначение | E4: Обязательность | F4: Проверка | G4: Бизнес-смысл
A5: R-01 | B5: Система.owner_position_id | C5: многие-к-одному | D5: Позиции.position_id | E5: необязательная | F5: FK из Система!AC | G5: Кто отвечает за систему
A6: R-02 | B6: Система.current_version_id | C6: многие-к-одному | D6: Версии.version_id | E6: необязательная | F6: FK из Система!AE | G6: Какая версия сейчас действует
A7: R-03 | B7: Продукты.system_id | C7: многие-к-одному | D7: Система.system_id | E7: обязательная | F7: FK из Система!W | G7: Какая система производит продукт
A8: R-04 | B8: Продукты.recipient_system_id | C8: многие-к-одному | D8: Система.system_id | E8: альтернатива позиции | F8: FK из Система!W | G8: Кому передаётся продукт
A9: R-05 | B9: Версии.system_id | C9: многие-к-одному | D9: Система.system_id | E9: обязательная | F9: FK из Система!W | G9: Версия какой системы
A10: R-06 | B10: Позиции.system_id | C10: многие-к-одному | D10: Система.system_id | E10: обязательная | F10: FK из Система!W | G10: В какой системе живёт ответственность
A11: R-07 | B11: Назначения.position_id | C11: многие-к-одному | D11: Позиции.position_id | E11: обязательная | F11: FK из Система!AC | G11: Кто исполняет позицию
A12: R-08 | B12: Процессы.system_id | C12: многие-к-одному | D12: Система.system_id | E12: обязательная | F12: FK из Система!W | G12: Контур процесса
A13: R-09 | B13: Процессы.parent_process_id | C13: многие-к-одному | D13: Процессы.process_id | E13: необязательная | F13: FK из Система!Y | G13: Иерархия процессов
A14: R-10 | B14: Процессы.work_object_id | C14: многие-к-одному | D14: Объекты.object_id | E14: рекомендуемая | F14: FK из Система!AA | G14: Что преобразует процесс
A15: R-11 | B15: Процессы.owner_position_id | C15: многие-к-одному | D15: Позиции.position_id | E15: обязательная | F15: FK из Система!AC | G15: Кто отвечает за результат процесса
... A39: R-35 | B39: Проекция draw.io.element_id | C39: один-к-одному | D39: action_id / edge_id / производный event/lane ID | E39: обязательная | F39: проверяется генератором | G39: Стабильная идентичность элементов draw.io

Sheet Источники
A1: Источники
A2: Реестр оснований модели. Каждое существенное утверждение ссылается на источник и уровень его авторитетности.
A3: Жёлтый заголовок — обязательное поле. ID стабилен и не переиспользуется. Выбирайте связанные сущности только из выпадающих списков; основание фиксируйте в source_id.
A4: ID источника source_id * | B4: Название title * | C4: Тип источника source_type * | D4: Ссылка url | E4: Уровень авторитетности authority_level * | F4: Владелец источника owner_position_id | G4: Минимальный статус доверия trust_floor * | H4: Действует с valid_from | I4: Действует до valid_to | J4: Последняя проверка last_checked * | K4: Активен active * | L4: Примечания notes
A5: src-001 | B5: Решение владельца о корневой ПС и продукте | C5: решение владельца | E5: 1 — решение владельца | G5: принято | H5: 46234 | J5: 46234 | K5: да | L5: Подтверждено пользователем в рабочей сессии.
A6: src-002 | B6: Язык систематизации | C6: методология | D6: https://docs.google.com/document/d/1LhAthtkp47jQd5SmnLezPySHplHTwn23lyx02aYeBGY/edit | E6: 3 — регламент / документ | G6: принято | J6: 46234 | K6: да | L6: Методологический язык; не инвентаризация конкретной производственной системы.

Sheet Версии
A1: Версии
A2: Неизменяемые версии текущей и целевой модели. Изменение принятой модели оформляется новой версией.
A3: Жёлтый заголовок — обязательное поле. ID стабилен и не переиспользуется. Выбирайте связанные сущности только из выпадающих списков; основание фиксируйте в source_id.
A4: ID версии version_id * | B4: Производственная система system_id * | C4: Тип версии version_type * | D4: Метка версии version_label * | E4: Слой модели model_layer * | F4: Статус версии version_status * | G4: Действует с effective_from | H4: Кем принята accepted_by_position_id | I4: Свидетельство принятия acceptance_evidence | J4: Предыдущая версия predecessor_version_id | K4: Нужна миграция migration_required * | L4: Источник source_id * | M4: Примечания notes

Sheet Позиции
A1: Позиции
A2: Ответственность и полномочия в системе. Позиция не равна конкретному человеку.
A3: Жёлтый заголовок — обязательное поле. ID стабилен и не переиспользуется. Выбирайте связанные сущности только из выпадающих списков; основание фиксируйте в source_id.
A4: ID позиции position_id * | B4: Производственная система system_id * | C4: Название позиции position_name * | D4: Ответственность responsibility * | E4: Ожидаемый результат expected_result * | F4: Полномочия authority | G4: Владелец системы system_owner * | H4: Статус знания knowledge_status * | I4: Источник source_id * | J4: Актуализировано last_reviewed * | K4: Следующий аудит next_audit | L4: Примечания notes

Sheet Назначения
A1: Назначения
A2: Связь позиции с конкретным человеком или AI-агентом на заданный период.
A3: Жёлтый заголовок — обязательное поле. ID стабилен и не переиспользуется. Выбирайте связанные сущности только из выпадающих списков; основание фиксируйте в source_id.
A4: ID назначения assignment_id * | B4: Позиция position_id * | C4: Тип исполнителя performer_type * | D4: Исполнитель performer_name * | E4: Назначен с active_from | F4: Назначен до active_to | G4: Статус назначения assignment_status * | H4: Источник source_id * | I4: Примечания notes

Sheet Процессы
A1: Процессы
A2: Воспроизводимые преобразования объекта работы от триггера и входа к проверяемому выходу.
A3: Жёлтый заголовок — обязательное поле. ID стабилен и не переиспользуется. Выбирайте связанные сущности только из выпадающих списков; основание фиксируйте в source_id.
A4: ID процесса process_id * | B4: Производственная система system_id * | C4: Родительский процесс parent_process_id | D4: Группа / поток flow_tag | E4: Название процесса process_name * | F4: Цель goal * | G4: Объект работы work_object_id | H4: Триггер старта trigger * | I4: Вход process_input * | J4: Выход process_output * | K4: Начальное состояние entry_state_id | L4: Конечное состояние exit_state_id | M4: Ответственная позиция owner_position_id * | N4: Производимый продукт produced_product_id | O4: Слой модели model_layer * | P4: Версия version_id * | Q4: Статус исполнения execution_status * | R4: Статус знания knowledge_status * | S4: Источник source_id * | T4: Актуализировано last_reviewed * | U4: Следующий аудит next_audit | V4: Примечания notes

Sheet Действия
A1: Действия
A2: Минимальные управляемые единицы работы внутри процесса.
A3: Жёлтый заголовок — обязательное поле. ID стабилен и не переиспользуется. Выбирайте связанные сущности только из выпадающих списков; основание фиксируйте в source_id.
A4: ID действия action_id * | B4: Процесс process_id * | C4: Название действия action_name * | D4: Тип действия action_type * | E4: Назначение purpose | F4: Вход action_input * | G4: Выход action_output * | H4: Ответственная позиция responsible_position_id * | I4: Режим исполнения performer_mode * | J4: Механизм / интерфейс execution_element_id | K4: Ожидаемая длительность expected_duration | L4: Слой модели model_layer * | M4: Версия version_id * | N4: Статус исполнения execution_status * | O4: Статус знания knowledge_status * | P4: Источник source_id * | Q4: Актуализировано last_reviewed * | R4: Следующий аудит next_audit | S4: Примечания notes | T4: Входной объект input_object_id | U4: Выходной объект output_object_id | V4: Связанный подпроцесс linked_process_id | W4: Подпись на схеме diagram_label | X4: Показывать на схеме include_in_diagram * | Y4: Порядок на схеме diagram_order | Z4: Дорожка: переопределение lane_position_id

Sheet Связи действий
A1: Связи действий
A2: Порядок исполнения, ветвления, возвраты, исключения и контрольные точки.
A3: Жёлтый заголовок — обязательное поле. ID стабилен и не переиспользуется. Выбирайте связанные сущности только из выпадающих списков; основание фиксируйте в source_id.
A4: ID связи edge_id * | B4: Процесс process_id * | C4: От действия from_action_id | D4: Тип связи link_type * | E4: К действию to_action_id | F4: Условие condition_text | G4: Принимающая решение позиция decision_position_id | H4: Ожидаемое свидетельство expected_evidence | I4: Стартовая связь is_entry * | J4: Финальная связь is_terminal * | K4: Приоритет priority | L4: Статус знания knowledge_status * | M4: Источник source_id * | N4: Примечания notes | O4: Слой модели model_layer * | P4: Версия version_id * | Q4: Подпись ветки branch_label | R4: Ветка по умолчанию is_default * | S4: Показывать на схеме include_in_diagram * | T4: Порядок отрисовки diagram_order | U4: Актуализировано last_reviewed * | V4: Следующий аудит next_audit

Sheet Объекты
A1: Объекты
A2: То, что преобразуется, передаётся, хранится или используется производственной системой.
A3: Жёлтый заголовок — обязательное поле. ID стабилен и не переиспользуется. Выбирайте связанные сущности только из выпадающих списков; основание фиксируйте в source_id.
A4: ID объекта object_id * | B4: Производственная система system_id * | C4: Название объекта object_name * | D4: Тип объекта object_type * | E4: Определение definition * | F4: Канонический источник данных canonical_source_element_id | G4: Владелец данных data_owner_position_id | H4: Формат / схема format_or_schema | I4: Статус знания knowledge_status * | J4: Источник source_id * | K4: Актуализировано last_reviewed * | L4: Следующий аудит next_audit | M4: Примечания notes

Sheet Состояния
A1: Состояния
A2: Набор допустимых состояний объектов для текущей или целевой модели.
A3: Жёлтый заголовок — обязательное поле. ID стабилен и не переиспользуется. Выбирайте связанные сущности только из выпадающих списков; основание фиксируйте в source_id.
A4: ID состояния state_id * | B4: Объект object_id * | C4: Название состояния state_name * | D4: Определение definition * | E4: Терминальное terminal * | F4: Допустимые действия allowed_actions_summary | G4: Слой модели model_layer * | H4: Версия version_id * | I4: Статус знания knowledge_status * | J4: Источник source_id * | K4: Актуализировано last_reviewed * | L4: Следующий аудит next_audit | M4: Примечания notes

Sheet Переходы
A1: Переходы
A2: Проверяемые изменения состояния: что перевело объект, при каком условии и с каким свидетельством.
A3: Жёлтый заголовок — обязательное поле. ID стабилен и не переиспользуется. Выбирайте связанные сущности только из выпадающих списков; основание фиксируйте в source_id.
A4: ID перехода transition_id * | B4: Процесс process_id * | C4: Объект object_id * | D4: Из состояния from_state_id * | E4: В состояние to_state_id * | F4: Действие action_id | G4: Тип триггера trigger_type * | H4: Условие condition_text | I4: Принимающая решение позиция decision_position_id | J4: Свидетельство перехода evidence * | K4: Переход-исключение exception_transition_id | L4: Слой модели model_layer * | M4: Версия version_id * | N4: Статус знания knowledge_status * | O4: Источник source_id * | P4: Приоритет priority | Q4: Примечания notes

Sheet Элементы модели
A1: Элементы модели
A2: Регламенты, правила, данные, ИС, интерфейсы, метрики, нормативы, SLA, автоматизации и материалы.
A3: Жёлтый заголовок — обязательное поле. ID стабилен и не переиспользуется. Выбирайте связанные сущности только из выпадающих списков; основание фиксируйте в source_id.
A4: ID элемента element_id * | B4: Производственная система system_id * | C4: Тип элемента element_type * | D4: Название элемента element_name * | E4: Определение definition * | F4: Владелец owner_position_id | G4: Формула / правило formula_or_rule | H4: Единица / формат unit_or_format | I4: Цель / порог target_or_threshold | J4: Канонический источник данных canonical_source_element_id | K4: Слой модели model_layer * | L4: Версия version_id * | M4: Статус знания knowledge_status * | N4: Источник source_id * | O4: Актуализировано last_reviewed * | P4: Следующий аудит next_audit | Q4: Примечания notes

Sheet Контракты
A1: Контракты
A2: Интерфейс между производственными системами: продукт, пакет, критерии приёмки, SLA и возврат.
A3: Жёлтый заголовок — обязательное поле. ID стабилен и не переиспользуется. Выбирайте связанные сущности только из выпадающих списков; основание фиксируйте в source_id.
A4: ID контракта contract_id * | B4: Система-поставщик supplier_system_id * | C4: Система-получатель customer_system_id * | D4: Продукт product_id * | E4: Триггер передачи delivery_trigger * | F4: Формат передачи delivery_format * | G4: Пакет данных data_package | H4: Критерии приёмки acceptance_criteria * | I4: SLA SLA_element_id | J4: Возврат / исключение return_or_exception_path | K4: Кто меняет контракт change_authority_position_id | L4: Слой модели model_layer * | M4: Версия version_id * | N4: Статус знания knowledge_status * | O4: Источник source_id * | P4: Актуализировано last_reviewed * | Q4: Примечания notes

Sheet Связи модели
A1: Связи модели
A2: Ограниченный набор смысловых связей между сущностями. Порядок действий и переходы состояний ведутся отдельно.
A3: Жёлтый заголовок — обязательное поле. ID стабилен и не переиспользуется. Выбирайте связанные сущности только из выпадающих списков; основание фиксируйте в source_id.
A4: ID связи link_id * | B4: От сущности from_entity_id * | C4: Тип отношения relation_type * | D4: К сущности to_entity_id * | E4: Контур системы scope_system_id | F4: Контур процесса scope_process_id | G4: Слой модели model_layer * | H4: Версия version_id * | I4: Статус знания knowledge_status * | J4: Источник source_id * | K4: Примечания notes

Sheet Проверки
A1: Проверки целостности модели
A2: Красные строки блокируют принятие версии; жёлтые требуют осознанного решения владельца модели.
A3: Результат пересчитывается из канонических реестров. Ноль означает, что нарушение не найдено.
A4: Категория | B4: Проверка | C4: Результат | D4: Статус | E4: Что сделать
A5: Настройка | B5: Количество настроенных производственных систем | C5: =COUNTA('Система'!A5:A14) -> 1 | D5: =IF(C5>0,"норма","инфо") -> норма | E5: Добавьте хотя бы одну систему
A6: Продукт | B6: Продукты без критериев приёмки | C6: =COUNTIFS('Система'!A18:A27,"<>",'Система'!G18:G27,"") -> 0 | D6: =IF(C6=0,"норма","ошибка") -> норма | E6: Опишите проверяемое принятие продукта получателем
A7: ID | B7: Дубли ID производственных систем | C7: {=SUMPRODUCT((COUNTIF('Система'!A5:A14,'Система'!A5:A14)>1)*('Система'!A5:A14<>""))} -> 0 | D7: =IF(C7=0,"норма","ошибка") -> норма | E7: Назначьте уникальные стабильные ID
A8: ID | B8: Дубли ID продуктов | C8: {=SUMPRODUCT((COUNTIF('Система'!A18:A27,'Система'!A18:A27)>1)*('Система'!A18:A27<>""))} -> 0 | D8: =IF(C8=0,"норма","ошибка") -> норма | E8: Назначьте уникальные стабильные ID
A9: ID | B9: Дубли ID источников | C9: {=SUMPRODUCT((COUNTIF('Источники'!A5:A204,'Источники'!A5:A204)>1)*('Источники'!A5:A204<>""))} -> 0 | D9: =IF(C9=0,"норма","ошибка") -> норма | E9: Устраните дубли
A10: ID | B10: Дубли ID версий | C10: {=SUMPRODUCT((COUNTIF('Версии'!A5:A104,'Версии'!A5:A104)>1)*('Версии'!A5:A104<>""))} -> 0 | D10: =IF(C10=0,"норма","ошибка") -> норма | E10: Устраните дубли
A11: ID | B11: Дубли ID позиций | C11: {=SUMPRODUCT((COUNTIF('Позиции'!A5:A204,'Позиции'!A5:A204)>1)*('Позиции'!A5:A204<>""))} -> 0 | D11: =IF(C11=0,"норма","ошибка") -> норма | E11: Устраните дубли
A12: ID | B12: Дубли ID назначений | C12: {=SUMPRODUCT((COUNTIF('Назначения'!A5:A204,'Назначения'!A5:A204)>1)*('Назначения'!A5:A204<>""))} -> 0 | D12: =IF(C12=0,"норма","ошибка") -> норма | E12: Устраните дубли
A13: ID | B13: Дубли ID процессов | C13: {=SUMPRODUCT((COUNTIF('Процессы'!A5:A204,'Процессы'!A5:A204)>1)*('Процессы'!A5:A204<>""))} -> 0 | D13: =IF(C13=0,"норма","ошибка") -> норма | E13: Устраните дубли
A14: ID | B14: Дубли ID действий | C14: {=SUMPRODUCT((COUNTIF('Действия'!A5:A304,'Действия'!A5:A304)>1)*('Действия'!A5:A304<>""))} -> 0 | D14: =IF(C14=0,"норма","ошибка") -> норма | E14: Устраните дубли
A15: ID | B15: Дубли ID связей действий | C15: {=SUMPRODUCT((COUNTIF('Связи действий'!A5:A304,'Связи действий'!A5:A304)>1)*('Связи действий'!A5:A304<>""))} -> 0 | D15: =IF(C15=0,"норма","ошибка") -> норма | E15: Устраните дубли
A16: ID | B16: Дубли ID объектов | C16: {=SUMPRODUCT((COUNTIF('Объекты'!A5:A204,'Объекты'!A5:A204)>1)*('Объекты'!A5:A204<>""))} -> 0 | D16: =IF(C16=0,"норма","ошибка") -> норма | E16: Устраните дубли
A17: ID | B17: Дубли ID состояний | C17: {=SUMPRODUCT((COUNTIF('Состояния'!A5:A304,'Состояния'!A5:A304)>1)*('Состояния'!A5:A304<>""))} -> 0 | D17: =IF(C17=0,"норма","ошибка") -> норма | E17: Устраните дубли
A18: ID | B18: Дубли ID переходов | C18: {=SUMPRODUCT((COUNTIF('Переходы'!A5:A304,'Переходы'!A5:A304)>1)*('Переходы'!A5:A304<>""))} -> 0 | D18: =IF(C18=0,"норма","ошибка") -> норма | E18: Устраните дубли
A19: ID | B19: Дубли ID элементов модели | C19: {=SUMPRODUCT((COUNTIF('Элементы модели'!A5:A304,'Элементы модели'!A5:A304)>1)*('Элементы модели'!A5:A304<>""))} -> 0 | D19: =IF(C19=0,"норма","ошибка") -> норма | E19: Устраните дубли
A20: ID | B20: Дубли ID контрактов | C20: {=SUMPRODUCT((COUNTIF('Контракты'!A5:A104,'Контракты'!A5:A104)>1)*('Контракты'!A5:A104<>""))} -> 0 | D20: =IF(C20=0,"норма","ошибка") -> норма | E20: Устраните дубли
A21: ID | B21: Дубли ID связей модели | C21: {=SUMPRODUCT((COUNTIF('Связи модели'!A5:A304,'Связи модели'!A5:A304)>1)*('Связи модели'!A5:A304<>""))} -> 0 | D21: =IF(C21=0,"норма","ошибка") -> норма | E21: Устраните дубли
A22: Процессы | B22: Процессы без обязательного паспорта | C22: =SUMPRODUCT(('Процессы'!A5:A204<>"")*((('Процессы'!B5:B204="")+('Процессы'!E5:E204="")+('Процессы'!F5:F204="")+('Процессы'!H5:H204="")+('Процессы'!I5:I204="")+('Процессы'!J5:J204="")+('Процессы'!M5:M204="")+('Процессы'!O5:O204="")+('Процессы'!P5:P204="")+('Процессы'!R5:R204="")+('Процессы'!S5:S204=""))>0)) -> 0 | D22: =IF(C22=0,"норма","ошибка") -> норма | E22: Заполните паспорт процесса
A23: Действия | B23: Действия без обязательного паспорта | C23: =SUMPRODUCT(('Действия'!A5:A304<>"")*((('Действия'!B5:B304="")+('Действия'!C5:C304="")+('Действия'!F5:F304="")+('Действия'!G5:G304="")+('Действия'!H5:H304="")+('Действия'!L5:L304="")+('Действия'!M5:M304="")+('Действия'!O5:O304="")+('Действия'!P5:P304=""))>0)) -> 0 | D23: =IF(C23=0,"норма","ошибка") -> норма | E23: Заполните паспорт действия
A24: Состояния | B24: Состояния без объекта | C24: =COUNTIFS('Состояния'!A5:A304,"<>",'Состояния'!B5:B304,"") -> 0 | D24: =IF(C24=0,"норма","ошибка") -> норма | E24: Свяжите состояние с объектом
A25: Переходы | B25: Переходы без обязательного паспорта | C25: =SUMPRODUCT(('Переходы'!A5:A304<>"")*((('Переходы'!B5:B304="")+('Переходы'!C5:C304="")+('Переходы'!D5:D304="")+('Переходы'!E5:E304="")+('Переходы'!J5:J304=""))>0)) -> 0 | D25: =IF(C25=0,"норма","ошибка") -> норма | E25: Заполните процесс, объект, состояния и свидетельство
A26: Контракты | B26: Контракты без критериев приёмки | C26: =COUNTIFS('Контракты'!A5:A104,"<>",'Контракты'!H5:H104,"") -> 0 | D26: =IF(C26=0,"норма","ошибка") -> норма | E26: Опишите критерии приёмки
A27: Связи | B27: Смысловые связи без концов или типа | C27: =SUMPRODUCT(('Связи модели'!A5:A304<>"")*((('Связи модели'!B5:B304="")+('Связи модели'!C5:C304="")+('Связи модели'!D5:D304=""))>0)) -> 0 | D27: =IF(C27=0,"норма","ошибка") -> норма | E27: Заполните обе сущности и допустимый тип отношения
A28: Версии | B28: Строки текущего / целевого слоя без версии | C28: =COUNTIFS('Процессы'!A5:A204,"<>",'Процессы'!O5:O204,"<>",'Процессы'!P5:P204,"")+COUNTIFS('Действия'!A5:A304,"<>",'Действия'!L5:L304,"<>",'Действия'!M5:M304,"")+COUNTIFS('Состояния'!A5:A304,"<>",'Состояния'!G5:G304,"<>",'Состояния'!H5:H304,"")+COUNTIFS('Переходы'!A5:A304,"<>",'Переходы'!L5:L304,"<>",'Переходы'!M5:M304,"") -> 0 | D28: =IF(C28=0,"норма","ошибка") -> норма | E28: Назначьте версию каждой строке модели
A29: Позиции | B29: Позиции без ответственности или результата | C29: =SUMPRODUCT(('Позиции'!A5:A204<>"")*((('Позиции'!D5:D204="")+('Позиции'!E5:E204=""))>0)) -> 0 | D29: =IF(C29=0,"норма","предупреждение") -> норма | E29: Уточните ответственность и ожидаемый результат
A30: Связи действий | B30: Связи без слоя или версии | C30: =SUMPRODUCT(('Связи действий'!A5:A304<>"")*((('Связи действий'!O5:O304="")+('Связи действий'!P5:P304=""))>0)) -> 0 | D30: =IF(C30=0,"норма","ошибка") -> норма | E30: Заполните слой и версию каждой связи
A31: Действия | B31: Действия без признака показа на схеме | C31: =COUNTIFS('Действия'!A5:A304,"<>",'Действия'!X5:X304,"") -> 0 | D31: =IF(C31=0,"норма","ошибка") -> норма | E31: Укажите «да» или «нет»
A32: Связи действий | B32: Связи без признака показа на схеме | C32: =COUNTIFS('Связи действий'!A5:A304,"<>",'Связи действий'!S5:S304,"") -> 0 | D32: =IF(C32=0,"норма","ошибка") -> норма | E32: Укажите «да» или «нет»
A33: Действия | B33: Подпроцессы без связанного процесса | C33: =COUNTIFS('Действия'!A5:A304,"<>",'Действия'!D5:D304,"подпроцесс",'Действия'!V5:V304,"") -> 0 | D33: =IF(C33=0,"норма","ошибка") -> норма | E33: Заполните linked_process_id
A34: Диаграммы | B34: Диаграммы без обязательного паспорта | C34: =SUMPRODUCT(('Диаграммы'!A5:A104<>"")*((('Диаграммы'!B5:B104="")+('Диаграммы'!C5:C104="")+('Диаграммы'!D5:D104="")+('Диаграммы'!E5:E104="")+('Диаграммы'!F5:F104="")+('Диаграммы'!G5:G104="")+('Диаграммы'!H5:H104="")+('Диаграммы'!I5:I104="")+('Диаграммы'!J5:J104="")+('Диаграммы'!P5:P104="")+('Диаграммы'!Q5:Q104=""))>0)) -> 0 | D34: =IF(C34=0,"норма","ошибка") -> норма | E34: Заполните обязательные поля диаграммы
A35: Диаграммы | B35: Процессы без настройки диаграммы | C35: {=SUM(IF('Процессы'!A5:A204="",0,--(COUNTIF('Диаграммы'!B5:B104,'Процессы'!A5:A204)=0)))} -> 0 | D35: =IF(C35=0,"норма","предупреждение") -> норма | E35: Создайте diagram_id для каждого моделируемого процесса
A36: Связи действий | B36: Процессы без стартовой связи | C36: {=SUM(IF('Процессы'!A5:A204="",0,--(COUNTIFS('Связи действий'!B5:B304,'Процессы'!A5:A204,'Связи действий'!I5:I304,"да")=0)))} -> 0 | D36: =IF(C36=0,"норма","предупреждение") -> норма | E36: Добавьте вход в первое действие
A37: Связи действий | B37: Процессы без финальной связи | C37: {=SUM(IF('Процессы'!A5:A204="",0,--(COUNTIFS('Связи действий'!B5:B304,'Процессы'!A5:A204,'Связи действий'!J5:J304,"да")=0)))} -> 0 | D37: =IF(C37=0,"норма","предупреждение") -> норма | E37: Добавьте выход из последнего действия
A38: Решения | B38: Ветвления без подписи ветки | C38: =COUNTIFS('Связи действий'!A5:A304,"<>",'Связи действий'!D5:D304,"ветвление",'Связи действий'!Q5:Q304,"") -> 0 | D38: =IF(C38=0,"норма","ошибка") -> норма | E38: Подпишите каждую ветку решения
A39: Диаграммы | B39: Схемы не сгенерированы или требуют обновления | C39: =COUNTIFS('Диаграммы'!A5:A104,"<>",'Диаграммы'!M5:M104,"не сгенерирована")+COUNTIFS('Диаграммы'!A5:A104,"<>",'Диаграммы'!M5:M104,"требует обновления") -> 0 | D39: =IF(C39=0,"норма","предупреждение") -> норма | E39: Пересоберите draw.io и обновите дату/отпечаток
A40: Решения | B40: Решения менее чем с двумя исходящими связями | C40: {=SUM(IF(('Действия'!A5:A304<>"")*('Действия'!D5:D304="решение"),--(COUNTIFS('Связи действий'!C5:C304,'Действия'!A5:A304,'Связи действий'!S5:S304,"да")<2),0))} -> 0 | D40: =IF(C40=0,"норма","ошибка") -> норма | E40: Добавьте как минимум две подписанные ветки
...

Sheet Реестр процессов
A1: Реестр процессов — вычисляемое представление
A2: Не заполняйте этот лист вручную. Он собирает читаемый обзор из канонических реестров и показывает неполный паспорт.
A3: Источник истины — листы «Процессы», «Действия», «Связи действий», «Переходы», «Позиции», «Диаграммы» и «Система».
A4: ID процесса process_id | B4: Производственная система production_system | C4: Родитель parent_process_id | D4: Название process_name | E4: Цель goal | F4: Триггер trigger | G4: Вход input | H4: Выход output | I4: Владелец owner_position | J4: Действий action_count | K4: Переходов state_transition_count | L4: Слой model_layer | M4: Версия version_id | N4: Исполнение execution_status | O4: Знание knowledge_status | P4: Источник source_id | Q4: Полнота completeness_status | R4: Диаграмма diagram_id | S4: Синхронизация схемы diagram_sync_status | T4: Файл draw.io drawio_url
A5: =IF('Процессы'!A5="","",'Процессы'!A5) | B5: {=IF($A5="","",IFERROR(INDEX('Система'!$B$5:$B$14,MATCH('Процессы'!B5,'Система'!$A$5:$A$14,0)),"⚠ ID системы"))} | C5: =IF($A5="","",'Процессы'!C5) | D5: =IF($A5="","",'Процессы'!E5) | E5: =IF($A5="","",'Процессы'!F5) | F5: =IF($A5="","",'Процессы'!H5) | G5: =IF($A5="","",'Процессы'!I5) | H5: =IF($A5="","",'Процессы'!J5) | I5: {=IF($A5="","",IFERROR(INDEX('Позиции'!$C$5:$C$204,MATCH('Процессы'!M5,'Позиции'!$A$5:$A$204,0)),"⚠ ID позиции"))} | J5: =IF($A5="","",COUNTIF('Действия'!$B$5:$B$304,$A5)) | K5: =IF($A5="","",COUNTIF('Переходы'!$B$5:$B$304,$A5)) | L5: =IF($A5="","",'Процессы'!O5) | M5: =IF($A5="","",'Процессы'!P5) | N5: =IF($A5="","",'Процессы'!Q5) | O5: =IF($A5="","",'Процессы'!R5) | P5: =IF($A5="","",'Процессы'!S5) | Q5: =IF($A5="","",IF(COUNTA('Процессы'!B5,'Процессы'!E5,'Процессы'!F5,'Процессы'!H5,'Процессы'!I5,'Процессы'!J5,'Процессы'!M5,'Процессы'!O5,'Процессы'!P5,'Процессы'!R5,'Процессы'!S5)=11,"Готово","Есть пробелы")) | R5: {=IF($A5="","",IFERROR(INDEX('Диаграммы'!$A$5:$A$104,MATCH($A5,'Диаграммы'!$B$5:$B$104,0)),"не настроена"))} | S5: {=IF(OR($A5="",$R5="не настроена"),"",IFERROR(INDEX('Диаграммы'!$M$5:$M$104,MATCH($R5,'Диаграммы'!$A$5:$A$104,0)),""))} | T5: {=IF(OR($A5="",$R5="не настроена"),"",IFERROR(HYPERLINK(INDEX('Диаграммы'!$O$5:$O$104,MATCH($R5,'Диаграммы'!$A$5:$A$104,0)),"открыть"),""))}
A6: =IF('Процессы'!A6="","",'Процессы'!A6) | B6: {=IF($A6="","",IFERROR(INDEX('Система'!$B$5:$B$14,MATCH('Процессы'!B6,'Система'!$A$5:$A$14,0)),"⚠ ID системы"))} | C6: =IF($A6="","",'Процессы'!C6) | D6: =IF($A6="","",'Процессы'!E6) | E6: =IF($A6="","",'Процессы'!F6) | F6: =IF($A6="","",'Процессы'!H6) | G6: =IF($A6="","",'Процессы'!I6) | H6: =IF($A6="","",'Процессы'!J6) | I6: {=IF($A6="","",IFERROR(INDEX('Позиции'!$C$5:$C$204,MATCH('Процессы'!M6,'Позиции'!$A$5:$A$204,0)),"⚠ ID позиции"))} | J6: =IF($A6="","",COUNTIF('Действия'!$B$5:$B$304,$A6)) | K6: =IF($A6="","",COUNTIF('Переходы'!$B$5:$B$304,$A6)) | L6: =IF($A6="","",'Процессы'!O6) | M6: =IF($A6="","",'Процессы'!P6) | N6: =IF($A6="","",'Процессы'!Q6) | O6: =IF($A6="","",'Процессы'!R6) | P6: =IF($A6="","",'Процессы'!S6) | Q6: =IF($A6="","",IF(COUNTA('Процессы'!B6,'Процессы'!E6,'Процессы'!F6,'Процессы'!H6,'Процессы'!I6,'Процессы'!J6,'Процессы'!M6,'Процессы'!O6,'Процессы'!P6,'Процессы'!R6,'Процессы'!S6)=11,"Готово","Есть пробелы")) | R6: {=IF($A6="","",IFERROR(INDEX('Диаграммы'!$A$5:$A$104,MATCH($A6,'Диаграммы'!$B$5:$B$104,0)),"не настроена"))} | S6: {=IF(OR($A6="",$R6="не настроена"),"",IFERROR(INDEX('Диаграммы'!$M$5:$M$104,MATCH($R6,'Диаграммы'!$A$5:$A$104,0)),""))} | T6: {=IF(OR($A6="",$R6="не настроена"),"",IFERROR(HYPERLINK(INDEX('Диаграммы'!$O$5:$O$104,MATCH($R6,'Диаграммы'!$A$5:$A$104,0)),"открыть"),""))}
A7: =IF('Процессы'!A7="","",'Процессы'!A7) | B7: {=IF($A7="","",IFERROR(INDEX('Система'!$B$5:$B$14,MATCH('Процессы'!B7,'Система'!$A$5:$A$14,0)),"⚠ ID системы"))} | C7: =IF($A7="","",'Процессы'!C7) | D7: =IF($A7="","",'Процессы'!E7) | E7: =IF($A7="","",'Процессы'!F7) | F7: =IF($A7="","",'Процессы'!H7) | G7: =IF($A7="","",'Процессы'!I7) | H7: =IF($A7="","",'Процессы'!J7) | I7: {=IF($A7="","",IFERROR(INDEX('Позиции'!$C$5:$C$204,MATCH('Процессы'!M7,'Позиции'!$A$5:$A$204,0)),"⚠ ID позиции"))} | J7: =IF($A7="","",COUNTIF('Действия'!$B$5:$B$304,$A7)) | K7: =IF($A7="","",COUNTIF('Переходы'!$B$5:$B$304,$A7)) | L7: =IF($A7="","",'Процессы'!O7) | M7: =IF($A7="","",'Процессы'!P7) | N7: =IF($A7="","",'Процессы'!Q7) | O7: =IF($A7="","",'Процессы'!R7) | P7: =IF($A7="","",'Процессы'!S7) | Q7: =IF($A7="","",IF(COUNTA('Процессы'!B7,'Процессы'!E7,'Процессы'!F7,'Процессы'!H7,'Процессы'!I7,'Процессы'!J7,'Процессы'!M7,'Процессы'!O7,'Процессы'!P7,'Процессы'!R7,'Процессы'!S7)=11,"Готово","Есть пробелы")) | R7: {=IF($A7="","",IFERROR(INDEX('Диаграммы'!$A$5:$A$104,MATCH($A7,'Диаграммы'!$B$5:$B$104,0)),"не настроена"))} | S7: {=IF(OR($A7="",$R7="не настроена"),"",IFERROR(INDEX('Диаграммы'!$M$5:$M$104,MATCH($R7,'Диаграммы'!$A$5:$A$104,0)),""))} | T7: {=IF(OR($A7="",$R7="не настроена"),"",IFERROR(HYPERLINK(INDEX('Диаграммы'!$O$5:$O$104,MATCH($R7,'Диаграммы'!$A$5:$A$104,0)),"открыть"),""))}
A8: =IF('Процессы'!A8="","",'Процессы'!A8) | B8: {=IF($A8="","",IFERROR(INDEX('Система'!$B$5:$B$14,MATCH('Процессы'!B8,'Система'!$A$5:$A$14,0)),"⚠ ID системы"))} | C8: =IF($A8="","",'Процессы'!C8) | D8: =IF($A8="","",'Процессы'!E8) | E8: =IF($A8="","",'Процессы'!F8) | F8: =IF($A8="","",'Процессы'!H8) | G8: =IF($A8="","",'Процессы'!I8) | H8: =IF($A8="","",'Процессы'!J8) | I8: {=IF($A8="","",IFERROR(INDEX('Позиции'!$C$5:$C$204,MATCH('Процессы'!M8,'Позиции'!$A$5:$A$204,0)),"⚠ ID позиции"))} | J8: =IF($A8="","",COUNTIF('Действия'!$B$5:$B$304,$A8)) | K8: =IF($A8="","",COUNTIF('Переходы'!$B$5:$B$304,$A8)) | L8: =IF($A8="","",'Процессы'!O8) | M8: =IF($A8="","",'Процессы'!P8) | N8: =IF($A8="","",'Процессы'!Q8) | O8: =IF($A8="","",'Процессы'!R8) | P8: =IF($A8="","",'Процессы'!S8) | Q8: =IF($A8="","",IF(COUNTA('Процессы'!B8,'Процессы'!E8,'Процессы'!F8,'Процессы'!H8,'Процессы'!I8,'Процессы'!J8,'Процессы'!M8,'Процессы'!O8,'Процессы'!P8,'Процессы'!R8,'Процессы'!S8)=11,"Готово","Есть пробелы")) | R8: {=IF($A8="","",IFERROR(INDEX('Диаграммы'!$A$5:$A$104,MATCH($A8,'Диаграммы'!$B$5:$B$104,0)),"не настроена"))} | S8: {=IF(OR($A8="",$R8="не настроена"),"",IFERROR(INDEX('Диаграммы'!$M$5:$M$104,MATCH($R8,'Диаграммы'!$A$5:$A$104,0)),""))} | T8: {=IF(OR($A8="",$R8="не настроена"),"",IFERROR(HYPERLINK(INDEX('Диаграммы'!$O$5:$O$104,MATCH($R8,'Диаграммы'!$A$5:$A$104,0)),"открыть"),""))}
A9: =IF('Процессы'!A9="","",'Процессы'!A9) | B9: {=IF($A9="","",IFERROR(INDEX('Система'!$B$5:$B$14,MATCH('Процессы'!B9,'Система'!$A$5:$A$14,0)),"⚠ ID системы"))} | C9: =IF($A9="","",'Процессы'!C9) | D9: =IF($A9="","",'Процессы'!E9) | E9: =IF($A9="","",'Процессы'!F9) | F9: =IF($A9="","",'Процессы'!H9) | G9: =IF($A9="","",'Процессы'!I9) | H9: =IF($A9="","",'Процессы'!J9) | I9: {=IF($A9="","",IFERROR(INDEX('Позиции'!$C$5:$C$204,MATCH('Процессы'!M9,'Позиции'!$A$5:$A$204,0)),"⚠ ID позиции"))} | J9: =IF($A9="","",COUNTIF('Действия'!$B$5:$B$304,$A9)) | K9: =IF($A9="","",COUNTIF('Переходы'!$B$5:$B$304,$A9)) | L9: =IF($A9="","",'Процессы'!O9) | M9: =IF($A9="","",'Процессы'!P9) | N9: =IF($A9="","",'Процессы'!Q9) | O9: =IF($A9="","",'Процессы'!R9) | P9: =IF($A9="","",'Процессы'!S9) | Q9: =IF($A9="","",IF(COUNTA('Процессы'!B9,'Процессы'!E9,'Процессы'!F9,'Процессы'!H9,'Процессы'!I9,'Процессы'!J9,'Процессы'!M9,'Процессы'!O9,'Процессы'!P9,'Процессы'!R9,'Процессы'!S9)=11,"Готово","Есть пробелы")) | R9: {=IF($A9="","",IFERROR(INDEX('Диаграммы'!$A$5:$A$104,MATCH($A9,'Диаграммы'!$B$5:$B$104,0)),"не настроена"))} | S9: {=IF(OR($A9="",$R9="не настроена"),"",IFERROR(INDEX('Диаграммы'!$M$5:$M$104,MATCH($R9,'Диаграммы'!$A$5:$A$104,0)),""))} | T9: {=IF(OR($A9="",$R9="не настроена"),"",IFERROR(HYPERLINK(INDEX('Диаграммы'!$O$5:$O$104,MATCH($R9,'Диаграммы'!$A$5:$A$104,0)),"открыть"),""))}
A10: =IF('Процессы'!A10="","",'Процессы'!A10) | B10: {=IF($A10="","",IFERROR(INDEX('Система'!$B$5:$B$14,MATCH('Процессы'!B10,'Система'!$A$5:$A$14,0)),"⚠ ID системы"))} | C10: =IF($A10="","",'Процессы'!C10) | D10: =IF($A10="","",'Процессы'!E10) | E10: =IF($A10="","",'Процессы'!F10) | F10: =IF($A10="","",'Процессы'!H10) | G10: =IF($A10="","",'Процессы'!I10) | H10: =IF($A10="","",'Процессы'!J10) | I10: {=IF($A10="","",IFERROR(INDEX('Позиции'!$C$5:$C$204,MATCH('Процессы'!M10,'Позиции'!$A$5:$A$204,0)),"⚠ ID позиции"))} | J10: =IF($A10="","",COUNTIF('Действия'!$B$5:$B$304,$A10)) | K10: =IF($A10="","",COUNTIF('Переходы'!$B$5:$B$304,$A10)) | L10: =IF($A10="","",'Процессы'!O10) | M10: =IF($A10="","",'Процессы'!P10) | N10: =IF($A10="","",'Процессы'!Q10) | O10: =IF($A10="","",'Процессы'!R10) | P10: =IF($A10="","",'Процессы'!S10) | Q10: =IF($A10="","",IF(COUNTA('Процессы'!B10,'Процессы'!E10,'Процессы'!F10,'Процессы'!H10,'Процессы'!I10,'Процессы'!J10,'Процессы'!M10,'Процессы'!O10,'Процессы'!P10,'Процессы'!R10,'Процессы'!S10)=11,"Готово","Есть пробелы")) | R10: {=IF($A10="","",IFERROR(INDEX('Диаграммы'!$A$5:$A$104,MATCH($A10,'Диаграммы'!$B$5:$B$104,0)),"не настроена"))} | S10: {=IF(OR($A10="",$R10="не настроена"),"",IFERROR(INDEX('Диаграммы'!$M$5:$M$104,MATCH($R10,'Диаграммы'!$A$5:$A$104,0)),""))} | T10: {=IF(OR($A10="",$R10="не настроена"),"",IFERROR(HYPERLINK(INDEX('Диаграммы'!$O$5:$O$104,MATCH($R10,'Диаграммы'!$A$5:$A$104,0)),"открыть"),""))}
A11: =IF('Процессы'!A11="","",'Процессы'!A11) | B11: {=IF($A11="","",IFERROR(INDEX('Система'!$B$5:$B$14,MATCH('Процессы'!B11,'Система'!$A$5:$A$14,0)),"⚠ ID системы"))} | C11: =IF($A11="","",'Процессы'!C11) | D11: =IF($A11="","",'Процессы'!E11) | E11: =IF($A11="","",'Процессы'!F11) | F11: =IF($A11="","",'Процессы'!H11) | G11: =IF($A11="","",'Процессы'!I11) | H11: =IF($A11="","",'Процессы'!J11) | I11: {=IF($A11="","",IFERROR(INDEX('Позиции'!$C$5:$C$204,MATCH('Процессы'!M11,'Позиции'!$A$5:$A$204,0)),"⚠ ID позиции"))} | J11: =IF($A11="","",COUNTIF('Действия'!$B$5:$B$304,$A11)) | K11: =IF($A11="","",COUNTIF('Переходы'!$B$5:$B$304,$A11)) | L11: =IF($A11="","",'Процессы'!O11) | M11: =IF($A11="","",'Процессы'!P11) | N11: =IF($A11="","",'Процессы'!Q11) | O11: =IF($A11="","",'Процессы'!R11) | P11: =IF($A11="","",'Процессы'!S11) | Q11: =IF($A11="","",IF(COUNTA('Процессы'!B11,'Процессы'!E11,'Процессы'!F11,'Процессы'!H11,'Процессы'!I11,'Процессы'!J11,'Процессы'!M11,'Процессы'!O11,'Процессы'!P11,'Процессы'!R11,'Процессы'!S11)=11,"Готово","Есть пробелы")) | R11: {=IF($A11="","",IFERROR(INDEX('Диаграммы'!$A$5:$A$104,MATCH($A11,'Диаграммы'!$B$5:$B$104,0)),"не настроена"))} | S11: {=IF(OR($A11="",$R11="не настроена"),"",IFERROR(INDEX('Диаграммы'!$M$5:$M$104,MATCH($R11,'Диаграммы'!$A$5:$A$104,0)),""))} | T11: {=IF(OR($A11="",$R11="не настроена"),"",IFERROR(HYPERLINK(INDEX('Диаграммы'!$O$5:$O$104,MATCH($R11,'Диаграммы'!$A$5:$A$104,0)),"открыть"),""))}
A12: =IF('Процессы'!A12="","",'Процессы'!A12) | B12: {=IF($A12="","",IFERROR(INDEX('Система'!$B$5:$B$14,MATCH('Процессы'!B12,'Система'!$A$5:$A$14,0)),"⚠ ID системы"))} | C12: =IF($A12="","",'Процессы'!C12) | D12: =IF($A12="","",'Процессы'!E12) | E12: =IF($A12="","",'Процессы'!F12) | F12: =IF($A12="","",'Процессы'!H12) | G12: =IF($A12="","",'Процессы'!I12) | H12: =IF($A12="","",'Процессы'!J12) | I12: {=IF($A12="","",IFERROR(INDEX('Позиции'!$C$5:$C$204,MATCH('Процессы'!M12,'Позиции'!$A$5:$A$204,0)),"⚠ ID позиции"))} | J12: =IF($A12="","",COUNTIF('Действия'!$B$5:$B$304,$A12)) | K12: =IF($A12="","",COUNTIF('Переходы'!$B$5:$B$304,$A12)) | L12: =IF($A12="","",'Процессы'!O12) | M12: =IF($A12="","",'Процессы'!P12) | N12: =IF($A12="","",'Процессы'!Q12) | O12: =IF($A12="","",'Процессы'!R12) | P12: =IF($A12="","",'Процессы'!S12) | Q12: =IF($A12="","",IF(COUNTA('Процессы'!B12,'Процессы'!E12,'Процессы'!F12,'Процессы'!H12,'Процессы'!I12,'Процессы'!J12,'Процессы'!M12,'Процессы'!O12,'Процессы'!P12,'Процессы'!R12,'Процессы'!S12)=11,"Готово","Есть пробелы")) | R12: {=IF($A12="","",IFERROR(INDEX('Диаграммы'!$A$5:$A$104,MATCH($A12,'Диаграммы'!$B$5:$B$104,0)),"не настроена"))} | S12: {=IF(OR($A12="",$R12="не настроена"),"",IFERROR(INDEX('Диаграммы'!$M$5:$M$104,MATCH($R12,'Диаграммы'!$A$5:$A$104,0)),""))} | T12: {=IF(OR($A12="",$R12="не настроена"),"",IFERROR(HYPERLINK(INDEX('Диаграммы'!$O$5:$O$104,MATCH($R12,'Диаграммы'!$A$5:$A$104,0)),"открыть"),""))}
A13: =IF('Процессы'!A13="","",'Процессы'!A13) | B13: {=IF($A13="","",IFERROR(INDEX('Система'!$B$5:$B$14,MATCH('Процессы'!B13,'Система'!$A$5:$A$14,0)),"⚠ ID системы"))} | C13: =IF($A13="","",'Процессы'!C13) | D13: =IF($A13="","",'Процессы'!E13) | E13: =IF($A13="","",'Процессы'!F13) | F13: =IF($A13="","",'Процессы'!H13) | G13: =IF($A13="","",'Процессы'!I13) | H13: =IF($A13="","",'Процессы'!J13) | I13: {=IF($A13="","",IFERROR(INDEX('Позиции'!$C$5:$C$204,MATCH('Процессы'!M13,'Позиции'!$A$5:$A$204,0)),"⚠ ID позиции"))} | J13: =IF($A13="","",COUNTIF('Действия'!$B$5:$B$304,$A13)) | K13: =IF($A13="","",COUNTIF('Переходы'!$B$5:$B$304,$A13)) | L13: =IF($A13="","",'Процессы'!O13) | M13: =IF($A13="","",'Процессы'!P13) | N13: =IF($A13="","",'Процессы'!Q13) | O13: =IF($A13="","",'Процессы'!R13) | P13: =IF($A13="","",'Процессы'!S13) | Q13: =IF($A13="","",IF(COUNTA('Процессы'!B13,'Процессы'!E13,'Процессы'!F13,'Процессы'!H13,'Процессы'!I13,'Процессы'!J13,'Процессы'!M13,'Процессы'!O13,'Процессы'!P13,'Процессы'!R13,'Процессы'!S13)=11,"Готово","Есть пробелы")) | R13: {=IF($A13="","",IFERROR(INDEX('Диаграммы'!$A$5:$A$104,MATCH($A13,'Диаграммы'!$B$5:$B$104,0)),"не настроена"))} | S13: {=IF(OR($A13="",$R13="не настроена"),"",IFERROR(INDEX('Диаграммы'!$M$5:$M$104,MATCH($R13,'Диаграммы'!$A$5:$A$104,0)),""))} | T13: {=IF(OR($A13="",$R13="не настроена"),"",IFERROR(HYPERLINK(INDEX('Диаграммы'!$O$5:$O$104,MATCH($R13,'Диаграммы'!$A$5:$A$104,0)),"открыть"),""))}
A14: =IF('Процессы'!A14="","",'Процессы'!A14) | B14: {=IF($A14="","",IFERROR(INDEX('Система'!$B$5:$B$14,MATCH('Процессы'!B14,'Система'!$A$5:$A$14,0)),"⚠ ID системы"))} | C14: =IF($A14="","",'Процессы'!C14) | D14: =IF($A14="","",'Процессы'!E14) | E14: =IF($A14="","",'Процессы'!F14) | F14: =IF($A14="","",'Процессы'!H14) | G14: =IF($A14="","",'Процессы'!I14) | H14: =IF($A14="","",'Процессы'!J14) | I14: {=IF($A14="","",IFERROR(INDEX('Позиции'!$C$5:$C$204,MATCH('Процессы'!M14,'Позиции'!$A$5:$A$204,0)),"⚠ ID позиции"))} | J14: =IF($A14="","",COUNTIF('Действия'!$B$5:$B$304,$A14)) | K14: =IF($A14="","",COUNTIF('Переходы'!$B$5:$B$304,$A14)) | L14: =IF($A14="","",'Процессы'!O14) | M14: =IF($A14="","",'Процессы'!P14) | N14: =IF($A14="","",'Процессы'!Q14) | O14: =IF($A14="","",'Процессы'!R14) | P14: =IF($A14="","",'Процессы'!S14) | Q14: =IF($A14="","",IF(COUNTA('Процессы'!B14,'Процессы'!E14,'Процессы'!F14,'Процессы'!H14,'Процессы'!I14,'Процессы'!J14,'Процессы'!M14,'Процессы'!O14,'Процессы'!P14,'Процессы'!R14,'Процессы'!S14)=11,"Готово","Есть пробелы")) | R14: {=IF($A14="","",IFERROR(INDEX('Диаграммы'!$A$5:$A$104,MATCH($A14,'Диаграммы'!$B$5:$B$104,0)),"не настроена"))} | S14: {=IF(OR($A14="",$R14="не настроена"),"",IFERROR(INDEX('Диаграммы'!$M$5:$M$104,MATCH($R14,'Диаграммы'!$A$5:$A$104,0)),""))} | T14: {=IF(OR($A14="",$R14="не настроена"),"",IFERROR(HYPERLINK(INDEX('Диаграммы'!$O$5:$O$104,MATCH($R14,'Диаграммы'!$A$5:$A$104,0)),"открыть"),""))}
A15: =IF('Процессы'!A15="","",'Процессы'!A15) | B15: {=IF($A15="","",IFERROR(INDEX('Система'!$B$5:$B$14,MATCH('Процессы'!B15,'Система'!$A$5:$A$14,0)),"⚠ ID системы"))} | C15: =IF($A15="","",'Процессы'!C15) | D15: =IF($A15="","",'Процессы'!E15) | E15: =IF($A15="","",'Процессы'!F15) | F15: =IF($A15="","",'Процессы'!H15) | G15: =IF($A15="","",'Процессы'!I15) | H15: =IF($A15="","",'Процессы'!J15) | I15: {=IF($A15="","",IFERROR(INDEX('Позиции'!$C$5:$C$204,MATCH('Процессы'!M15,'Позиции'!$A$5:$A$204,0)),"⚠ ID позиции"))} | J15: =IF($A15="","",COUNTIF('Действия'!$B$5:$B$304,$A15)) | K15: =IF($A15="","",COUNTIF('Переходы'!$B$5:$B$304,$A15)) | L15: =IF($A15="","",'Процессы'!O15) | M15: =IF($A15="","",'Процессы'!P15) | N15: =IF($A15="","",'Процессы'!Q15) | O15: =IF($A15="","",'Процессы'!R15) | P15: =IF($A15="","",'Процессы'!S15) | Q15: =IF($A15="","",IF(COUNTA('Процессы'!B15,'Процессы'!E15,'Процессы'!F15,'Процессы'!H15,'Процессы'!I15,'Процессы'!J15,'Процессы'!M15,'Процессы'!O15,'Процессы'!P15,'Процессы'!R15,'Процессы'!S15)=11,"Готово","Есть пробелы")) | R15: {=IF($A15="","",IFERROR(INDEX('Диаграммы'!$A$5:$A$104,MATCH($A15,'Диаграммы'!$B$5:$B$104,0)),"не настроена"))} | S15: {=IF(OR($A15="",$R15="не настроена"),"",IFERROR(INDEX('Диаграммы'!$M$5:$M$104,MATCH($R15,'Диаграммы'!$A$5:$A$104,0)),""))} | T15: {=IF(OR($A15="",$R15="не настроена"),"",IFERROR(HYPERLINK(INDEX('Диаграммы'!$O$5:$O$104,MATCH($R15,'Диаграммы'!$A$5:$A$104,0)),"открыть"),""))}
A16: =IF('Процессы'!A16="","",'Процессы'!A16) | B16: {=IF($A16="","",IFERROR(INDEX('Система'!$B$5:$B$14,MATCH('Процессы'!B16,'Система'!$A$5:$A$14,0)),"⚠ ID системы"))} | C16: =IF($A16="","",'Процессы'!C16) | D16: =IF($A16="","",'Процессы'!E16) | E16: =IF($A16="","",'Процессы'!F16) | F16: =IF($A16="","",'Процессы'!H16) | G16: =IF($A16="","",'Процессы'!I16) | H16: =IF($A16="","",'Процессы'!J16) | I16: {=IF($A16="","",IFERROR(INDEX('Позиции'!$C$5:$C$204,MATCH('Процессы'!M16,'Позиции'!$A$5:$A$204,0)),"⚠ ID позиции"))} | J16: =IF($A16="","",COUNTIF('Действия'!$B$5:$B$304,$A16)) | K16: =IF($A16="","",COUNTIF('Переходы'!$B$5:$B$304,$A16)) | L16: =IF($A16="","",'Процессы'!O16) | M16: =IF($A16="","",'Процессы'!P16) | N16: =IF($A16="","",'Процессы'!Q16) | O16: =IF($A16="","",'Процессы'!R16) | P16: =IF($A16="","",'Процессы'!S16) | Q16: =IF($A16="","",IF(COUNTA('Процессы'!B16,'Процессы'!E16,'Процессы'!F16,'Процессы'!H16,'Процессы'!I16,'Процессы'!J16,'Процессы'!M16,'Процессы'!O16,'Процессы'!P16,'Процессы'!R16,'Процессы'!S16)=11,"Готово","Есть пробелы")) | R16: {=IF($A16="","",IFERROR(INDEX('Диаграммы'!$A$5:$A$104,MATCH($A16,'Диаграммы'!$B$5:$B$104,0)),"не настроена"))} | S16: {=IF(OR($A16="",$R16="не настроена"),"",IFERROR(INDEX('Диаграммы'!$M$5:$M$104,MATCH($R16,'Диаграммы'!$A$5:$A$104,0)),""))} | T16: {=IF(OR($A16="",$R16="не настроена"),"",IFERROR(HYPERLINK(INDEX('Диаграммы'!$O$5:$O$104,MATCH($R16,'Диаграммы'!$A$5:$A$104,0)),"открыть"),""))}
... A204: =IF('Процессы'!A204="","",'Процессы'!A204) | B204: {=IF($A204="","",IFERROR(INDEX('Система'!$B$5:$B$14,MATCH('Процессы'!B204,'Система'!$A$5:$A$14,0)),"⚠ ID системы"))} | C204: =IF($A204="","",'Процессы'!C204) | D204: =IF($A204="","",'Процессы'!E204) | E204: =IF($A204="","",'Процессы'!F204) | F204: =IF($A204="","",'Процессы'!H204) | G204: =IF($A204="","",'Процессы'!I204) | H204: =IF($A204="","",'Процессы'!J204) | I204: {=IF($A204="","",IFERROR(INDEX('Позиции'!$C$5:$C$204,MATCH('Процессы'!M204,'Позиции'!$A$5:$A$204,0)),"⚠ ID позиции"))} | J204: =IF($A204="","",COUNTIF('Действия'!$B$5:$B$304,$A204)) | K204: =IF($A204="","",COUNTIF('Переходы'!$B$5:$B$304,$A204)) | L204: =IF($A204="","",'Процессы'!O204) | M204: =IF($A204="","",'Процессы'!P204) | N204: =IF($A204="","",'Процессы'!Q204) | O204: =IF($A204="","",'Процессы'!R204) | P204: =IF($A204="","",'Процессы'!S204) | Q204: =IF($A204="","",IF(COUNTA('Процессы'!B204,'Процессы'!E204,'Процессы'!F204,'Процессы'!H204,'Процессы'!I204,'Процессы'!J204,'Процессы'!M204,'Процессы'!O204,'Процессы'!P204,'Процессы'!R204,'Процессы'!S204)=11,"Готово","Есть пробелы")) | R204: {=IF($A204="","",IFERROR(INDEX('Диаграммы'!$A$5:$A$104,MATCH($A204,'Диаграммы'!$B$5:$B$104,0)),"не настроена"))} | S204: {=IF(OR($A204="",$R204="не настроена"),"",IFERROR(INDEX('Диаграммы'!$M$5:$M$104,MATCH($R204,'Диаграммы'!$A$5:$A$104,0)),""))} | T204: {=IF(OR($A204="",$R204="не настроена"),"",IFERROR(HYPERLINK(INDEX('Диаграммы'!$O$5:$O$104,MATCH($R204,'Диаграммы'!$A$5:$A$104,0)),"открыть"),""))}

Sheet Рабочая панель
A1: Рабочая панель модели
A2: Выберите систему и процесс. Панель собирает паспорт и исполнимую логику без ручного копирования.
A3: Система | B3: ps-001
A4: Название | B4: {=IFERROR(INDEX('Система'!$B$5:$B$14,MATCH($B$3,'Система'!$A$5:$A$14,0)),"")} -> Привлечение
A5: Назначение | B5: {=IFERROR(INDEX('Система'!$D$5:$D$14,MATCH($B$3,'Система'!$A$5:$A$14,0)),"")} -> Производить потенциального участника, принятого принимающей стороной и переданного в клуб с согласованным пакетом
A6: Продукт | B6: {=IFERROR(INDEX('Система'!$C$18:$C$27,MATCH($B$3,'Система'!$B$18:$B$27,0)),"")} -> Потенциальный участник, принятый принимающей стороной и переданный в клуб
A7: Критерии приёмки | B7: {=IFERROR(INDEX('Система'!$G$18:$G$27,MATCH($B$3,'Система'!$B$18:$B$27,0)),"")} -> Принимающая сторона приняла участника; согласованный пакет передан
A8: Позиция-владелец | B8: {=IFERROR(INDEX('Система'!$E$5:$E$14,MATCH($B$3,'Система'!$A$5:$A$14,0)),"не назначена")}
A9: Текущая версия | B9: {=IFERROR(INDEX('Система'!$F$5:$F$14,MATCH($B$3,'Система'!$A$5:$A$14,0)),"не назначена")}
A10: Статус знания | B10: {=IFERROR(INDEX('Система'!$G$5:$G$14,MATCH($B$3,'Система'!$A$5:$A$14,0)),"")} -> принято
A12: Процесс
A13: Название | B13: {=IFERROR(INDEX('Процессы'!$E$5:$E$204,MATCH($B$12,'Процессы'!$A$5:$A$204,0)),"")}
A14: Цель | B14: {=IFERROR(INDEX('Процессы'!$F$5:$F$204,MATCH($B$12,'Процессы'!$A$5:$A$204,0)),"")}
A15: Триггер | B15: {=IFERROR(INDEX('Процессы'!$H$5:$H$204,MATCH($B$12,'Процессы'!$A$5:$A$204,0)),"")}
A16: Вход | B16: {=IFERROR(INDEX('Процессы'!$I$5:$I$204,MATCH($B$12,'Процессы'!$A$5:$A$204,0)),"")}
A17: Выход | B17: {=IFERROR(INDEX('Процессы'!$J$5:$J$204,MATCH($B$12,'Процессы'!$A$5:$A$204,0)),"")}
A18: Позиция-владелец | B18: {=IFERROR(INDEX('Процессы'!$M$5:$M$204,MATCH($B$12,'Процессы'!$A$5:$A$204,0)),"")}
A19: Слой | B19: {=IFERROR(INDEX('Процессы'!$O$5:$O$204,MATCH($B$12,'Процессы'!$A$5:$A$204,0)),"")}
A20: Версия | B20: {=IFERROR(INDEX('Процессы'!$P$5:$P$204,MATCH($B$12,'Процессы'!$A$5:$A$204,0)),"")}
A21: Диаграмма | B21: {=IFERROR(INDEX('Диаграммы'!$A$5:$A$104,MATCH($B$12,'Диаграммы'!$B$5:$B$104,0)),"не настроена")} -> не настроена | D21: Синхронизация | E21: {=IFERROR(INDEX('Диаграммы'!$M$5:$M$104,MATCH($B$21,'Диаграммы'!$A$5:$A$104,0)),"")} | G21: Файл | H21: {=IFERROR(HYPERLINK(INDEX('Диаграммы'!$O$5:$O$104,MATCH($B$21,'Диаграммы'!$A$5:$A$104,0)),"открыть"),"—")} -> —
A22: Действия выбранного процесса
A23: ID | B23: Действие | C23: Тип | D23: Вход | E23: Выход | F23: Позиция | G23: Режим | H23: Статус
A24: =IFERROR(__xludf.DUMMYFUNCTION("IF($B$12="""","""",IFERROR(FILTER({'Действия'!A5:A304,'Действия'!C5:C304,'Действия'!D5:D304,'Действия'!F5:F304,'Действия'!G5:G304,'Действия'!H5:H304,'Действия'!I5:I304,'Действия'!N5:N304},'Действия'!B5:B304=$B$12),""""))"),"")
A330: Переходы состояний выбранного процесса
A331: ID | B331: Объект | C331: Из состояния | D331: В состояние | E331: Действие | F331: Триггер | G331: Условие | H331: Свидетельство
A332: =IFERROR(__xludf.DUMMYFUNCTION("IF($B$12="""","""",IFERROR(FILTER({'Переходы'!A5:A304,'Переходы'!C5:C304,'Переходы'!D5:D304,'Переходы'!E5:E304,'Переходы'!F5:F304,'Переходы'!G5:G304,'Переходы'!H5:H304,'Переходы'!J5:J304},'Переходы'!B5:B304=$B$12),""""))"),"")

Sheet Диаграммы
A1: Диаграммы процессов
A2: Конфигурация и контроль актуальности схем. Геометрия draw.io является производным представлением реестров «Процессы», «Действия» и «Связи действий».
A3: Жёлтый заголовок — обязательное поле. ID диаграммы стабилен. После генерации запишите дату, отпечаток модели и ссылку на файл; статус синхронизации рассчитывается автоматически.
